Internal Server Error: /flashcards/next/
Traceback (most recent call last):
  File "E:\ANACONDA\envs\anki\lib\site-packages\django\core\handlers\exception.py", line 34, in inner
    response = get_response(request)
  File "E:\ANACONDA\envs\anki\lib\site-packages\django\core\handlers\base.py", line 115, in _get_response
    response = self.process_exception_by_middleware(e, request)
  File "E:\ANACONDA\envs\anki\lib\site-packages\django\core\handlers\base.py", line 113, in _get_response
    response = wrapped_callback(request, *callback_args, **callback_kwargs)
  File "E:\ANACONDA\envs\anki\lib\site-packages\django\contrib\auth\decorators.py", line 21, in _wrapped_view
    return view_func(request, *args, **kwargs)
  File "E:\All Files\Programmaing\Suki\flashcards\views.py", line 104, in nextcardview
    return redirect("card_detailview", 43191)
  File "E:\ANACONDA\envs\anki\lib\site-packages\django\shortcuts.py", line 41, in redirect
    return redirect_class(resolve_url(to, *args, **kwargs))
  File "E:\ANACONDA\envs\anki\lib\site-packages\django\shortcuts.py", line 131, in resolve_url
    return reverse(to, args=args, kwargs=kwargs)
  File "E:\ANACONDA\envs\anki\lib\site-packages\django\urls\base.py", line 87, in reverse
    return iri_to_uri(resolver._reverse_with_prefix(view, prefix, *args, **kwargs))
  File "E:\ANACONDA\envs\anki\lib\site-packages\django\urls\resolvers.py", line 677, in _reverse_with_prefix
    raise NoReverseMatch(msg)
django.urls.exceptions.NoReverseMatch: Reverse for 'card_detailview' not found. 'card_detailview' is not a valid view function or pattern name.
"GET /flashcards/next/ HTTP/1.1" 500 98812
Internal Server Error: /flashcards/next/
Traceback (most recent call last):
  File "E:\ANACONDA\envs\anki\lib\site-packages\django\core\handlers\exception.py", line 34, in inner
    response = get_response(request)
  File "E:\ANACONDA\envs\anki\lib\site-packages\django\core\handlers\base.py", line 115, in _get_response
    response = self.process_exception_by_middleware(e, request)
  File "E:\ANACONDA\envs\anki\lib\site-packages\django\core\handlers\base.py", line 113, in _get_response
    response = wrapped_callback(request, *callback_args, **callback_kwargs)
  File "E:\ANACONDA\envs\anki\lib\site-packages\django\contrib\auth\decorators.py", line 21, in _wrapped_view
    return view_func(request, *args, **kwargs)
  File "E:\All Files\Programmaing\Suki\flashcards\views.py", line 104, in nextcardview
    return redirect("next", 43191)
  File "E:\ANACONDA\envs\anki\lib\site-packages\django\shortcuts.py", line 41, in redirect
    return redirect_class(resolve_url(to, *args, **kwargs))
  File "E:\ANACONDA\envs\anki\lib\site-packages\django\shortcuts.py", line 131, in resolve_url
    return reverse(to, args=args, kwargs=kwargs)
  File "E:\ANACONDA\envs\anki\lib\site-packages\django\urls\base.py", line 87, in reverse
    return iri_to_uri(resolver._reverse_with_prefix(view, prefix, *args, **kwargs))
  File "E:\ANACONDA\envs\anki\lib\site-packages\django\urls\resolvers.py", line 677, in _reverse_with_prefix
    raise NoReverseMatch(msg)
django.urls.exceptions.NoReverseMatch: Reverse for 'next' not found. 'next' is not a valid view function or pattern name.
"GET /flashcards/next/ HTTP/1.1" 500 98759
Internal Server Error: /flashcards/next/
Traceback (most recent call last):
  File "E:\ANACONDA\envs\anki\lib\site-packages\django\core\handlers\exception.py", line 34, in inner
    response = get_response(request)
  File "E:\ANACONDA\envs\anki\lib\site-packages\django\core\handlers\base.py", line 115, in _get_response
    response = self.process_exception_by_middleware(e, request)
  File "E:\ANACONDA\envs\anki\lib\site-packages\django\core\handlers\base.py", line 113, in _get_response
    response = wrapped_callback(request, *callback_args, **callback_kwargs)
  File "E:\ANACONDA\envs\anki\lib\site-packages\django\contrib\auth\decorators.py", line 21, in _wrapped_view
    return view_func(request, *args, **kwargs)
  File "E:\All Files\Programmaing\Suki\flashcards\views.py", line 104, in nextcardview
    return redirect("card_detail", 43191)
  File "E:\ANACONDA\envs\anki\lib\site-packages\django\shortcuts.py", line 41, in redirect
    return redirect_class(resolve_url(to, *args, **kwargs))
  File "E:\ANACONDA\envs\anki\lib\site-packages\django\shortcuts.py", line 131, in resolve_url
    return reverse(to, args=args, kwargs=kwargs)
  File "E:\ANACONDA\envs\anki\lib\site-packages\django\urls\base.py", line 87, in reverse
    return iri_to_uri(resolver._reverse_with_prefix(view, prefix, *args, **kwargs))
  File "E:\ANACONDA\envs\anki\lib\site-packages\django\urls\resolvers.py", line 677, in _reverse_with_prefix
    raise NoReverseMatch(msg)
django.urls.exceptions.NoReverseMatch: Reverse for 'card_detail' not found. 'card_detail' is not a valid view function or pattern name.
"GET /flashcards/next/ HTTP/1.1" 500 98746
Internal Server Error: /flashcards/next/
Traceback (most recent call last):
  File "E:\ANACONDA\envs\anki\lib\site-packages\django\core\handlers\exception.py", line 34, in inner
    response = get_response(request)
  File "E:\ANACONDA\envs\anki\lib\site-packages\django\core\handlers\base.py", line 115, in _get_response
    response = self.process_exception_by_middleware(e, request)
  File "E:\ANACONDA\envs\anki\lib\site-packages\django\core\handlers\base.py", line 113, in _get_response
    response = wrapped_callback(request, *callback_args, **callback_kwargs)
  File "E:\ANACONDA\envs\anki\lib\site-packages\django\contrib\auth\decorators.py", line 21, in _wrapped_view
    return view_func(request, *args, **kwargs)
  File "E:\All Files\Programmaing\Suki\flashcards\views.py", line 104, in nextcardview
    return redirect("card_detailview", 43191)
  File "E:\ANACONDA\envs\anki\lib\site-packages\django\shortcuts.py", line 41, in redirect
    return redirect_class(resolve_url(to, *args, **kwargs))
  File "E:\ANACONDA\envs\anki\lib\site-packages\django\shortcuts.py", line 131, in resolve_url
    return reverse(to, args=args, kwargs=kwargs)
  File "E:\ANACONDA\envs\anki\lib\site-packages\django\urls\base.py", line 87, in reverse
    return iri_to_uri(resolver._reverse_with_prefix(view, prefix, *args, **kwargs))
  File "E:\ANACONDA\envs\anki\lib\site-packages\django\urls\resolvers.py", line 677, in _reverse_with_prefix
    raise NoReverseMatch(msg)
django.urls.exceptions.NoReverseMatch: Reverse for 'card_detailview' not found. 'card_detailview' is not a valid view function or pattern name.
"GET /flashcards/next/ HTTP/1.1" 500 98819
Internal Server Error: /flashcards/next/
Traceback (most recent call last):
  File "E:\ANACONDA\envs\anki\lib\site-packages\django\core\handlers\exception.py", line 34, in inner
    response = get_response(request)
  File "E:\ANACONDA\envs\anki\lib\site-packages\django\core\handlers\base.py", line 115, in _get_response
    response = self.process_exception_by_middleware(e, request)
  File "E:\ANACONDA\envs\anki\lib\site-packages\django\core\handlers\base.py", line 113, in _get_response
    response = wrapped_callback(request, *callback_args, **callback_kwargs)
  File "E:\ANACONDA\envs\anki\lib\site-packages\django\contrib\auth\decorators.py", line 21, in _wrapped_view
    return view_func(request, *args, **kwargs)
  File "E:\All Files\Programmaing\Suki\flashcards\views.py", line 104, in nextcardview
    return redirect(card_detailview, 43191)
  File "E:\ANACONDA\envs\anki\lib\site-packages\django\shortcuts.py", line 41, in redirect
    return redirect_class(resolve_url(to, *args, **kwargs))
  File "E:\ANACONDA\envs\anki\lib\site-packages\django\shortcuts.py", line 131, in resolve_url
    return reverse(to, args=args, kwargs=kwargs)
  File "E:\ANACONDA\envs\anki\lib\site-packages\django\urls\base.py", line 87, in reverse
    return iri_to_uri(resolver._reverse_with_prefix(view, prefix, *args, **kwargs))
  File "E:\ANACONDA\envs\anki\lib\site-packages\django\urls\resolvers.py", line 677, in _reverse_with_prefix
    raise NoReverseMatch(msg)
django.urls.exceptions.NoReverseMatch: Reverse for 'flashcards.views.card_detailview' not found. 'flashcards.views.card_detailview' is not a valid view function or pattern name.
"GET /flashcards/next/ HTTP/1.1" 500 98497
Internal Server Error: /flashcards/next/
Traceback (most recent call last):
  File "E:\ANACONDA\envs\anki\lib\site-packages\django\core\handlers\exception.py", line 34, in inner
    response = get_response(request)
  File "E:\ANACONDA\envs\anki\lib\site-packages\django\core\handlers\base.py", line 115, in _get_response
    response = self.process_exception_by_middleware(e, request)
  File "E:\ANACONDA\envs\anki\lib\site-packages\django\core\handlers\base.py", line 113, in _get_response
    response = wrapped_callback(request, *callback_args, **callback_kwargs)
  File "E:\ANACONDA\envs\anki\lib\site-packages\django\contrib\auth\decorators.py", line 21, in _wrapped_view
    return view_func(request, *args, **kwargs)
  File "E:\All Files\Programmaing\Suki\flashcards\views.py", line 104, in nextcardview
    return redirect('card_detail', 43191)
  File "E:\ANACONDA\envs\anki\lib\site-packages\django\shortcuts.py", line 41, in redirect
    return redirect_class(resolve_url(to, *args, **kwargs))
  File "E:\ANACONDA\envs\anki\lib\site-packages\django\shortcuts.py", line 131, in resolve_url
    return reverse(to, args=args, kwargs=kwargs)
  File "E:\ANACONDA\envs\anki\lib\site-packages\django\urls\base.py", line 87, in reverse
    return iri_to_uri(resolver._reverse_with_prefix(view, prefix, *args, **kwargs))
  File "E:\ANACONDA\envs\anki\lib\site-packages\django\urls\resolvers.py", line 677, in _reverse_with_prefix
    raise NoReverseMatch(msg)
django.urls.exceptions.NoReverseMatch: Reverse for 'card_detail' not found. 'card_detail' is not a valid view function or pattern name.
"GET /flashcards/next/ HTTP/1.1" 500 98878
Internal Server Error: /flashcards/next/
Traceback (most recent call last):
  File "E:\ANACONDA\envs\anki\lib\site-packages\django\core\handlers\exception.py", line 34, in inner
    response = get_response(request)
  File "E:\ANACONDA\envs\anki\lib\site-packages\django\core\handlers\base.py", line 115, in _get_response
    response = self.process_exception_by_middleware(e, request)
  File "E:\ANACONDA\envs\anki\lib\site-packages\django\core\handlers\base.py", line 113, in _get_response
    response = wrapped_callback(request, *callback_args, **callback_kwargs)
  File "E:\ANACONDA\envs\anki\lib\site-packages\django\contrib\auth\decorators.py", line 21, in _wrapped_view
    return view_func(request, *args, **kwargs)
  File "E:\All Files\Programmaing\Suki\flashcards\views.py", line 104, in nextcardview
    return redirect('card_detailview', 43191)
  File "E:\ANACONDA\envs\anki\lib\site-packages\django\shortcuts.py", line 41, in redirect
    return redirect_class(resolve_url(to, *args, **kwargs))
  File "E:\ANACONDA\envs\anki\lib\site-packages\django\shortcuts.py", line 131, in resolve_url
    return reverse(to, args=args, kwargs=kwargs)
  File "E:\ANACONDA\envs\anki\lib\site-packages\django\urls\base.py", line 87, in reverse
    return iri_to_uri(resolver._reverse_with_prefix(view, prefix, *args, **kwargs))
  File "E:\ANACONDA\envs\anki\lib\site-packages\django\urls\resolvers.py", line 677, in _reverse_with_prefix
    raise NoReverseMatch(msg)
django.urls.exceptions.NoReverseMatch: Reverse for 'card_detailview' not found. 'card_detailview' is not a valid view function or pattern name.
"GET /flashcards/next/ HTTP/1.1" 500 98825
Internal Server Error: /flashcards/
Traceback (most recent call last):
  File "E:\ANACONDA\envs\anki\lib\site-packages\django\core\handlers\exception.py", line 34, in inner
    response = get_response(request)
  File "E:\ANACONDA\envs\anki\lib\site-packages\django\core\handlers\base.py", line 115, in _get_response
    response = self.process_exception_by_middleware(e, request)
  File "E:\ANACONDA\envs\anki\lib\site-packages\django\core\handlers\base.py", line 113, in _get_response
    response = wrapped_callback(request, *callback_args, **callback_kwargs)
  File "E:\All Files\Git\OmniAnki\flashcards\views.py", line 44, in index
    wordlists = request.user.owner.all()
  File "E:\ANACONDA\envs\anki\lib\site-packages\django\utils\functional.py", line 225, in inner
    return func(self._wrapped, *args)
AttributeError: 'AnonymousUser' object has no attribute 'owner'
"GET /flashcards/ HTTP/1.1" 500 78307
Internal Server Error: /flashcards/
Traceback (most recent call last):
  File "E:\ANACONDA\envs\anki\lib\site-packages\django\core\handlers\exception.py", line 34, in inner
    response = get_response(request)
  File "E:\ANACONDA\envs\anki\lib\site-packages\django\core\handlers\base.py", line 115, in _get_response
    response = self.process_exception_by_middleware(e, request)
  File "E:\ANACONDA\envs\anki\lib\site-packages\django\core\handlers\base.py", line 113, in _get_response
    response = wrapped_callback(request, *callback_args, **callback_kwargs)
  File "E:\All Files\Git\OmniAnki\flashcards\views.py", line 44, in index
    wordlists = request.user.owner.all()
  File "E:\ANACONDA\envs\anki\lib\site-packages\django\utils\functional.py", line 225, in inner
    return func(self._wrapped, *args)
AttributeError: 'AnonymousUser' object has no attribute 'owner'
"GET /flashcards/ HTTP/1.1" 500 78392
Internal Server Error: /flashcards/
Traceback (most recent call last):
  File "E:\ANACONDA\envs\anki\lib\site-packages\django\core\handlers\exception.py", line 34, in inner
    response = get_response(request)
  File "E:\ANACONDA\envs\anki\lib\site-packages\django\core\handlers\base.py", line 115, in _get_response
    response = self.process_exception_by_middleware(e, request)
  File "E:\ANACONDA\envs\anki\lib\site-packages\django\core\handlers\base.py", line 113, in _get_response
    response = wrapped_callback(request, *callback_args, **callback_kwargs)
  File "E:\All Files\Git\OmniAnki\flashcards\views.py", line 44, in index
    wordlists = request.user.owner.all()
  File "E:\ANACONDA\envs\anki\lib\site-packages\django\utils\functional.py", line 225, in inner
    return func(self._wrapped, *args)
AttributeError: 'AnonymousUser' object has no attribute 'owner'
"GET /flashcards/ HTTP/1.1" 500 78392
Internal Server Error: /flashcards/
Traceback (most recent call last):
  File "E:\ANACONDA\envs\anki\lib\site-packages\django\core\handlers\exception.py", line 34, in inner
    response = get_response(request)
  File "E:\ANACONDA\envs\anki\lib\site-packages\django\core\handlers\base.py", line 115, in _get_response
    response = self.process_exception_by_middleware(e, request)
  File "E:\ANACONDA\envs\anki\lib\site-packages\django\core\handlers\base.py", line 113, in _get_response
    response = wrapped_callback(request, *callback_args, **callback_kwargs)
  File "E:\All Files\Git\OmniAnki\flashcards\views.py", line 46, in index
    wordlists = request.user.owner.all()
  File "E:\ANACONDA\envs\anki\lib\site-packages\django\utils\functional.py", line 225, in inner
    return func(self._wrapped, *args)
AttributeError: 'AnonymousUser' object has no attribute 'owner'
"GET /flashcards/ HTTP/1.1" 500 77493
Internal Server Error: /flashcards/71
Traceback (most recent call last):
  File "E:\ANACONDA\envs\anki\lib\site-packages\django\core\handlers\exception.py", line 34, in inner
    response = get_response(request)
  File "E:\ANACONDA\envs\anki\lib\site-packages\django\core\handlers\base.py", line 115, in _get_response
    response = self.process_exception_by_middleware(e, request)
  File "E:\ANACONDA\envs\anki\lib\site-packages\django\core\handlers\base.py", line 113, in _get_response
    response = wrapped_callback(request, *callback_args, **callback_kwargs)
  File "E:\All Files\Git\OmniAnki\flashcards\views.py", line 73, in card_detailview
    random_example = request.user.settings.all()[0] if cache.get('random_example') is None else cache.get(
  File "E:\ANACONDA\envs\anki\lib\site-packages\django\db\models\query.py", line 314, in __getitem__
    return qs._result_cache[0]
IndexError: list index out of range
"GET /flashcards/71 HTTP/1.1" 500 78908
Internal Server Error: /flashcards/1
Traceback (most recent call last):
  File "E:\ANACONDA\envs\anki\lib\site-packages\django\core\handlers\exception.py", line 34, in inner
    response = get_response(request)
  File "E:\ANACONDA\envs\anki\lib\site-packages\django\core\handlers\base.py", line 115, in _get_response
    response = self.process_exception_by_middleware(e, request)
  File "E:\ANACONDA\envs\anki\lib\site-packages\django\core\handlers\base.py", line 113, in _get_response
    response = wrapped_callback(request, *callback_args, **callback_kwargs)
  File "E:\All Files\Git\OmniAnki\flashcards\views.py", line 73, in card_detailview
    random_example = request.user.settings.all()[0] if cache.get('random_example') is None else cache.get(
  File "E:\ANACONDA\envs\anki\lib\site-packages\django\db\models\query.py", line 314, in __getitem__
    return qs._result_cache[0]
IndexError: list index out of range
"GET /flashcards/1 HTTP/1.1" 500 78730
Internal Server Error: /flashcards/21
Traceback (most recent call last):
  File "E:\ANACONDA\envs\anki\lib\site-packages\django\core\handlers\exception.py", line 34, in inner
    response = get_response(request)
  File "E:\ANACONDA\envs\anki\lib\site-packages\django\core\handlers\base.py", line 115, in _get_response
    response = self.process_exception_by_middleware(e, request)
  File "E:\ANACONDA\envs\anki\lib\site-packages\django\core\handlers\base.py", line 113, in _get_response
    response = wrapped_callback(request, *callback_args, **callback_kwargs)
  File "E:\All Files\Git\OmniAnki\flashcards\views.py", line 73, in card_detailview
    random_example = request.user.settings.all()[0] if cache.get('random_example') is None else cache.get(
  File "E:\ANACONDA\envs\anki\lib\site-packages\django\db\models\query.py", line 314, in __getitem__
    return qs._result_cache[0]
IndexError: list index out of range
"GET /flashcards/21 HTTP/1.1" 500 78746
Internal Server Error: /flashcards/13
Traceback (most recent call last):
  File "E:\ANACONDA\envs\anki\lib\site-packages\django\core\handlers\exception.py", line 34, in inner
    response = get_response(request)
  File "E:\ANACONDA\envs\anki\lib\site-packages\django\core\handlers\base.py", line 115, in _get_response
    response = self.process_exception_by_middleware(e, request)
  File "E:\ANACONDA\envs\anki\lib\site-packages\django\core\handlers\base.py", line 113, in _get_response
    response = wrapped_callback(request, *callback_args, **callback_kwargs)
  File "E:\All Files\Git\OmniAnki\flashcards\views.py", line 73, in card_detailview
    random_example = request.user.settings.all()[0] if cache.get('random_example') is None else cache.get(
  File "E:\ANACONDA\envs\anki\lib\site-packages\django\db\models\query.py", line 314, in __getitem__
    return qs._result_cache[0]
IndexError: list index out of range
"GET /flashcards/13 HTTP/1.1" 500 78908
Internal Server Error: /flashcards/dict/
Traceback (most recent call last):
  File "E:\ANACONDA\envs\anki\lib\site-packages\django\core\handlers\exception.py", line 34, in inner
    response = get_response(request)
  File "E:\ANACONDA\envs\anki\lib\site-packages\django\core\handlers\base.py", line 115, in _get_response
    response = self.process_exception_by_middleware(e, request)
  File "E:\ANACONDA\envs\anki\lib\site-packages\django\core\handlers\base.py", line 113, in _get_response
    response = wrapped_callback(request, *callback_args, **callback_kwargs)
  File "E:\ANACONDA\envs\anki\lib\site-packages\django\contrib\auth\decorators.py", line 21, in _wrapped_view
    return view_func(request, *args, **kwargs)
  File "E:\All Files\Git\OmniAnki\flashcards\views.py", line 238, in dict_search
    html_result = dict_query[0].item
  File "E:\ANACONDA\envs\anki\lib\site-packages\django\db\models\query.py", line 296, in __getitem__
    return self._result_cache[k]
IndexError: list index out of range
"GET /flashcards/dict/?query=run&csrfmiddlewaretoken=SQhO7xik7UeOOV4sPhbbZ4lOEftImofmVmIIE7GRG7M5NKRVxgIspVFJaxPpsodJ HTTP/1.1" 500 85700
Internal Server Error: /flashcards/dict/
Traceback (most recent call last):
  File "E:\ANACONDA\envs\anki\lib\site-packages\django\core\handlers\exception.py", line 34, in inner
    response = get_response(request)
  File "E:\ANACONDA\envs\anki\lib\site-packages\django\core\handlers\base.py", line 115, in _get_response
    response = self.process_exception_by_middleware(e, request)
  File "E:\ANACONDA\envs\anki\lib\site-packages\django\core\handlers\base.py", line 113, in _get_response
    response = wrapped_callback(request, *callback_args, **callback_kwargs)
  File "E:\ANACONDA\envs\anki\lib\site-packages\django\contrib\auth\decorators.py", line 21, in _wrapped_view
    return view_func(request, *args, **kwargs)
  File "E:\All Files\Git\OmniAnki\flashcards\views.py", line 238, in dict_search
    html_result = dict_query[0].item
  File "E:\ANACONDA\envs\anki\lib\site-packages\django\db\models\query.py", line 296, in __getitem__
    return self._result_cache[k]
IndexError: list index out of range
"GET /flashcards/dict/?query=run&csrfmiddlewaretoken=SQhO7xik7UeOOV4sPhbbZ4lOEftImofmVmIIE7GRG7M5NKRVxgIspVFJaxPpsodJ HTTP/1.1" 500 85700
Internal Server Error: /flashcards/recite_wordlist/1/0/0/
Traceback (most recent call last):
  File "E:\ANACONDA\envs\anki\lib\site-packages\django\core\handlers\exception.py", line 34, in inner
    response = get_response(request)
  File "E:\ANACONDA\envs\anki\lib\site-packages\django\core\handlers\base.py", line 115, in _get_response
    response = self.process_exception_by_middleware(e, request)
  File "E:\ANACONDA\envs\anki\lib\site-packages\django\core\handlers\base.py", line 113, in _get_response
    response = wrapped_callback(request, *callback_args, **callback_kwargs)
  File "E:\ANACONDA\envs\anki\lib\site-packages\django\contrib\auth\decorators.py", line 21, in _wrapped_view
    return view_func(request, *args, **kwargs)
  File "E:\All Files\Git\OmniAnki\flashcards\views.py", line 292, in recite_wordlist
    wordlist = WordList.objects.filter(id=wordlist_id)[0]
  File "E:\ANACONDA\envs\anki\lib\site-packages\django\db\models\query.py", line 314, in __getitem__
    return qs._result_cache[0]
IndexError: list index out of range
"GET /flashcards/recite_wordlist/1/0/0/ HTTP/1.1" 500 84964
Internal Server Error: /flashcards/40004
Traceback (most recent call last):
  File "E:\ANACONDA\envs\anki\lib\site-packages\django\core\handlers\exception.py", line 34, in inner
    response = get_response(request)
  File "E:\ANACONDA\envs\anki\lib\site-packages\django\core\handlers\base.py", line 115, in _get_response
    response = self.process_exception_by_middleware(e, request)
  File "E:\ANACONDA\envs\anki\lib\site-packages\django\core\handlers\base.py", line 113, in _get_response
    response = wrapped_callback(request, *callback_args, **callback_kwargs)
  File "E:\All Files\Git\OmniAnki\flashcards\views.py", line 100, in card_detailview
    return render(request,
  File "E:\ANACONDA\envs\anki\lib\site-packages\django\shortcuts.py", line 19, in render
    content = loader.render_to_string(template_name, context, request, using=using)
  File "E:\ANACONDA\envs\anki\lib\site-packages\django\template\loader.py", line 62, in render_to_string
    return template.render(context, request)
  File "E:\ANACONDA\envs\anki\lib\site-packages\django\template\backends\django.py", line 61, in render
    return self.template.render(context)
  File "E:\ANACONDA\envs\anki\lib\site-packages\django\template\base.py", line 171, in render
    return self._render(context)
  File "E:\ANACONDA\envs\anki\lib\site-packages\django\template\base.py", line 163, in _render
    return self.nodelist.render(context)
  File "E:\ANACONDA\envs\anki\lib\site-packages\django\template\base.py", line 936, in render
    bit = node.render_annotated(context)
  File "E:\ANACONDA\envs\anki\lib\site-packages\django\template\base.py", line 903, in render_annotated
    return self.render(context)
  File "E:\ANACONDA\envs\anki\lib\site-packages\django\template\loader_tags.py", line 150, in render
    return compiled_parent._render(context)
  File "E:\ANACONDA\envs\anki\lib\site-packages\django\template\base.py", line 163, in _render
    return self.nodelist.render(context)
  File "E:\ANACONDA\envs\anki\lib\site-packages\django\template\base.py", line 936, in render
    bit = node.render_annotated(context)
  File "E:\ANACONDA\envs\anki\lib\site-packages\django\template\base.py", line 903, in render_annotated
    return self.render(context)
  File "E:\ANACONDA\envs\anki\lib\site-packages\django\template\loader_tags.py", line 127, in render
    compiled_parent = self.get_parent(context)
  File "E:\ANACONDA\envs\anki\lib\site-packages\django\template\loader_tags.py", line 124, in get_parent
    return self.find_template(parent, context)
  File "E:\ANACONDA\envs\anki\lib\site-packages\django\template\loader_tags.py", line 103, in find_template
    template, origin = context.template.engine.find_template(
  File "E:\ANACONDA\envs\anki\lib\site-packages\django\template\engine.py", line 125, in find_template
    template = loader.get_template(name, skip=skip)
  File "E:\ANACONDA\envs\anki\lib\site-packages\django\template\loaders\base.py", line 29, in get_template
    return Template(
  File "E:\ANACONDA\envs\anki\lib\site-packages\django\template\base.py", line 156, in __init__
    self.nodelist = self.compile_nodelist()
  File "E:\ANACONDA\envs\anki\lib\site-packages\django\template\base.py", line 194, in compile_nodelist
    return parser.parse()
  File "E:\ANACONDA\envs\anki\lib\site-packages\django\template\base.py", line 477, in parse
    raise self.error(token, e)
  File "E:\ANACONDA\envs\anki\lib\site-packages\django\template\base.py", line 475, in parse
    compiled_result = compile_func(self, token)
  File "E:\ANACONDA\envs\anki\lib\site-packages\django\template\loader_tags.py", line 205, in do_block
    raise TemplateSyntaxError("'%s' tag with name '%s' appears more than once" % (bits[0], block_name))
django.template.exceptions.TemplateSyntaxError: 'block' tag with name 'Anki' appears more than once
"GET /flashcards/40004 HTTP/1.1" 500 193839
Internal Server Error: /flashcards/40004
Traceback (most recent call last):
  File "E:\ANACONDA\envs\anki\lib\site-packages\django\core\handlers\exception.py", line 34, in inner
    response = get_response(request)
  File "E:\ANACONDA\envs\anki\lib\site-packages\django\core\handlers\base.py", line 115, in _get_response
    response = self.process_exception_by_middleware(e, request)
  File "E:\ANACONDA\envs\anki\lib\site-packages\django\core\handlers\base.py", line 113, in _get_response
    response = wrapped_callback(request, *callback_args, **callback_kwargs)
  File "E:\All Files\Git\OmniAnki\flashcards\views.py", line 100, in card_detailview
    return render(request,
  File "E:\ANACONDA\envs\anki\lib\site-packages\django\shortcuts.py", line 19, in render
    content = loader.render_to_string(template_name, context, request, using=using)
  File "E:\ANACONDA\envs\anki\lib\site-packages\django\template\loader.py", line 62, in render_to_string
    return template.render(context, request)
  File "E:\ANACONDA\envs\anki\lib\site-packages\django\template\backends\django.py", line 61, in render
    return self.template.render(context)
  File "E:\ANACONDA\envs\anki\lib\site-packages\django\template\base.py", line 171, in render
    return self._render(context)
  File "E:\ANACONDA\envs\anki\lib\site-packages\django\template\base.py", line 163, in _render
    return self.nodelist.render(context)
  File "E:\ANACONDA\envs\anki\lib\site-packages\django\template\base.py", line 936, in render
    bit = node.render_annotated(context)
  File "E:\ANACONDA\envs\anki\lib\site-packages\django\template\base.py", line 903, in render_annotated
    return self.render(context)
  File "E:\ANACONDA\envs\anki\lib\site-packages\django\template\loader_tags.py", line 150, in render
    return compiled_parent._render(context)
  File "E:\ANACONDA\envs\anki\lib\site-packages\django\template\base.py", line 163, in _render
    return self.nodelist.render(context)
  File "E:\ANACONDA\envs\anki\lib\site-packages\django\template\base.py", line 936, in render
    bit = node.render_annotated(context)
  File "E:\ANACONDA\envs\anki\lib\site-packages\django\template\base.py", line 903, in render_annotated
    return self.render(context)
  File "E:\ANACONDA\envs\anki\lib\site-packages\django\template\loader_tags.py", line 127, in render
    compiled_parent = self.get_parent(context)
  File "E:\ANACONDA\envs\anki\lib\site-packages\django\template\loader_tags.py", line 124, in get_parent
    return self.find_template(parent, context)
  File "E:\ANACONDA\envs\anki\lib\site-packages\django\template\loader_tags.py", line 103, in find_template
    template, origin = context.template.engine.find_template(
  File "E:\ANACONDA\envs\anki\lib\site-packages\django\template\engine.py", line 125, in find_template
    template = loader.get_template(name, skip=skip)
  File "E:\ANACONDA\envs\anki\lib\site-packages\django\template\loaders\base.py", line 29, in get_template
    return Template(
  File "E:\ANACONDA\envs\anki\lib\site-packages\django\template\base.py", line 156, in __init__
    self.nodelist = self.compile_nodelist()
  File "E:\ANACONDA\envs\anki\lib\site-packages\django\template\base.py", line 194, in compile_nodelist
    return parser.parse()
  File "E:\ANACONDA\envs\anki\lib\site-packages\django\template\base.py", line 477, in parse
    raise self.error(token, e)
  File "E:\ANACONDA\envs\anki\lib\site-packages\django\template\base.py", line 475, in parse
    compiled_result = compile_func(self, token)
  File "E:\ANACONDA\envs\anki\lib\site-packages\django\template\loader_tags.py", line 205, in do_block
    raise TemplateSyntaxError("'%s' tag with name '%s' appears more than once" % (bits[0], block_name))
django.template.exceptions.TemplateSyntaxError: 'block' tag with name 'Anki' appears more than once
"GET /flashcards/40004 HTTP/1.1" 500 193859
